Workbook
Name aporte: APP!$D$17
Name patrimonio: APP!$D$20
Name QTD_anos: APP!$D$18
Name rendimento_carteira: APP!$D$13
Name salario: APP!$D$12
Name sugest_invest: APP!$D$14
Name taxa_rend_mensal: APP!$D$19

Sheet APP
B11: CONFIGURAÇÕES
B12: Salário | D12: 2500
B13: Rendimento Carteira | D13: 0.006
B14: Sugestão de investimento (30%) | D14: =D12*30% -> 750
B16: INVESTIMENTO MENSAL
B17: Quanto investir por mês? | D17: 360
B18: Por quantos anos? | D18: 3
B19: Taxa de rendimento mensal? | D19: 0.01079
B20: Patrimônio acumulado? | D20: =FV(taxa_rend_mensal,QTD_anos*12,aporte*(-1)) -> 15735.015
B21: Dividendos mensais? | D21: =patrimonio*rendimento_carteira -> 94.410088
B23: CENÁRIOS | D23: Dividendos
A24: 2 | B24: Quanto teria em 2 anos? | C24: =FV($D$19,$A24*12,$D$17*(-1)) -> 9801.9458 | D24: =C24*rendimento_carteira -> 58.811675
A25: 5 | B25: Quanto teria em 5 anos? | C25: =FV($D$19,$A25*12,$D$17*(-1)) -> 30159.689 | D25: =C25*rendimento_carteira -> 180.95813
A26: 10 | B26: Quanto teria em 10 anos? | C26: =FV($D$19,$A26*12,$D$17*(-1)) -> 87582.317 | D26: =C26*rendimento_carteira -> 525.4939
A27: 20 | B27: Quanto teria em 20 anos? | C27: =FV($D$19,$A27*12,$D$17*(-1)) -> 405071.42 | D27: =C27*rendimento_carteira -> 2430.4285
A28: 30 | B28: Quanto teria em 30 anos? | C28: =FV($D$19,$A28*12,$D$17*(-1)) -> 1555981.1 | D28: =C28*rendimento_carteira -> 9335.8865
B30: CENÁRIOS (30%) | D30: Dividendos
A31: 2 | B31: Quanto teria em 2 anos? | C31: =FV($D$19,$A31*12,sugest_invest*(-1)) -> 20420.72 | D31: =C31*rendimento_carteira -> 122.52432
A32: 5 | B32: Quanto teria em 5 anos? | C32: =FV($D$19,$A32*12,sugest_invest*(-1)) -> 62832.685 | D32: =C32*rendimento_carteira -> 376.99611
A33: 10 | B33: Quanto teria em 10 anos? | C33: =FV($D$19,$A33*12,sugest_invest*(-1)) -> 182463.16 | D33: =C33*rendimento_carteira -> 1094.779
A34: 20 | B34: Quanto teria em 20 anos? | C34: =FV($D$19,$A34*12,sugest_invest*(-1)) -> 843898.8 | D34: =C34*rendimento_carteira -> 5063.3928
A35: 30 | B35: Quanto teria em 30 anos? | C35: =FV($D$19,$A35*12,sugest_invest*(-1)) -> 3241627.2 | D35: =C35*rendimento_carteira -> 19449.763
B38: PERFIL | D38: Moderado
B39: Valor a ser investido po mês | D39: =aporte -> 360
B41: TIPO DE FII | C41: Percentual Sugerido | D41: Valores
B42: PAPEL | C42: =VLOOKUP($D$38&"-"&B42,LIST_APOIO!$B:$E,4,FALSE) -> 0.32 | D42: =C42*$D$39 -> 115.2
B43: TIJOLO | C43: =VLOOKUP($D$38&"-"&B43,LIST_APOIO!$B:$E,4,FALSE) -> 0.35 | D43: =C43*$D$39 -> 126
B44: HÍBRIDOS | C44: =VLOOKUP($D$38&"-"&B44,LIST_APOIO!$B:$E,4,FALSE) -> 0.08 | D44: =C44*$D$39 -> 28.8
B45: FOFs | C45: =VLOOKUP($D$38&"-"&B45,LIST_APOIO!$B:$E,4,FALSE) -> 0.05 | D45: =C45*$D$39 -> 18
B46: DESENVOLVIMENTO | C46: =VLOOKUP($D$38&"-"&B46,LIST_APOIO!$B:$E,4,FALSE) -> 0.1 | D46: =C46*$D$39 -> 36
B47: HOTELÁRIAS | C47: =VLOOKUP($D$38&"-"&B47,LIST_APOIO!$B:$E,4,FALSE) -> 0.1 | D47: =C47*$D$39 -> 36
D48: =SUM(D42:D47) -> 360
B60: PERFIL | D60: Moderado
B61: Valor sugerido por mês (30%) | D61: =sugest_invest -> 750
B63: TIPO DE FII | C63: Percentual Sugerido | D63: Valores
B64: PAPEL | C64: =VLOOKUP($D$60&"-"&B64,LIST_APOIO!$K:$N,4,FALSE) -> 0.32 | D64: =C64*$D$61 -> 240
B65: TIJOLO | C65: =VLOOKUP($D$60&"-"&B65,LIST_APOIO!$K:$N,4,FALSE) -> 0.35 | D65: =C65*$D$61 -> 262.5
B66: HÍBRIDOS | C66: =VLOOKUP($D$60&"-"&B66,LIST_APOIO!$K:$N,4,FALSE) -> 0.08 | D66: =C66*$D$61 -> 60
B67: FOFs | C67: =VLOOKUP($D$60&"-"&B67,LIST_APOIO!$K:$N,4,FALSE) -> 0.05 | D67: =C67*$D$61 -> 37.5
B68: DESENVOLVIMENTO | C68: =VLOOKUP($D$60&"-"&B68,LIST_APOIO!$K:$N,4,FALSE) -> 0.1 | D68: =C68*$D$61 -> 75
...

Sheet LIST_APOIO
B3: CHAVE | C3: PERFIL | D3: TIPO DE FII | E3: % | K3: CHAVE | L3: PERFIL | M3: TIPO DE FII | N3: %
B4: =C4&"-"&D4 -> Conservador-PAPEL | C4: Conservador | D4: PAPEL | E4: 0.3 | K4: =L4&"-"&M4 -> Conservador-PAPEL | L4: Conservador | M4: PAPEL | N4: 0.3
B5: =C5&"-"&D5 -> Conservador-TIJOLO | C5: Conservador | D5: TIJOLO | E5: 0.5 | K5: =L5&"-"&M5 -> Conservador-TIJOLO | L5: Conservador | M5: TIJOLO | N5: 0.5
B6: =C6&"-"&D6 -> Conservador-HÍBRIDOS | C6: Conservador | D6: HÍBRIDOS | E6: 0.1 | K6: =L6&"-"&M6 -> Conservador-HÍBRIDOS | L6: Conservador | M6: HÍBRIDOS | N6: 0.1
B7: =C7&"-"&D7 -> Conservador-FOFs | C7: Conservador | D7: FOFs | E7: 0.1 | K7: =L7&"-"&M7 -> Conservador-FOFs | L7: Conservador | M7: FOFs | N7: 0.1
B8: =C8&"-"&D8 -> Conservador-DESENVOLVIMENTO | C8: Conservador | D8: DESENVOLVIMENTO | E8: 0 | K8: =L8&"-"&M8 -> Conservador-DESENVOLVIMENTO | L8: Conservador | M8: DESENVOLVIMENTO | N8: 0
B9: =C9&"-"&D9 -> Conservador-HOTELÁRIAS | C9: Conservador | D9: HOTELÁRIAS | E9: 0 | K9: =L9&"-"&M9 -> Conservador-HOTELÁRIAS | L9: Conservador | M9: HOTELÁRIAS | N9: 0
B10: =C10&"-"&D10 -> Moderado-PAPEL | C10: Moderado | D10: PAPEL | E10: 0.32 | K10: =L10&"-"&M10 -> Moderado-PAPEL | L10: Moderado | M10: PAPEL | N10: 0.32
B11: =C11&"-"&D11 -> Moderado-TIJOLO | C11: Moderado | D11: TIJOLO | E11: 0.35 | K11: =L11&"-"&M11 -> Moderado-TIJOLO | L11: Moderado | M11: TIJOLO | N11: 0.35
B12: =C12&"-"&D12 -> Moderado-HÍBRIDOS | C12: Moderado | D12: HÍBRIDOS | E12: 0.08 | K12: =L12&"-"&M12 -> Moderado-HÍBRIDOS | L12: Moderado | M12: HÍBRIDOS | N12: 0.08
B13: =C13&"-"&D13 -> Moderado-FOFs | C13: Moderado | D13: FOFs | E13: 0.05 | K13: =L13&"-"&M13 -> Moderado-FOFs | L13: Moderado | M13: FOFs | N13: 0.05
B14: =C14&"-"&D14 -> Moderado-DESENVOLVIMENTO | C14: Moderado | D14: DESENVOLVIMENTO | E14: 0.1 | K14: =L14&"-"&M14 -> Moderado-DESENVOLVIMENTO | L14: Moderado | M14: DESENVOLVIMENTO | N14: 0.1
B15: =C15&"-"&D15 -> Moderado-HOTELÁRIAS | C15: Moderado | D15: HOTELÁRIAS | E15: 0.1 | K15: =L15&"-"&M15 -> Moderado-HOTELÁRIAS | L15: Moderado | M15: HOTELÁRIAS | N15: 0.1
... B21: =C21&"-"&D21 -> Agressivo-HOTELÁRIAS | C21: Agressivo | D21: HOTELÁRIAS | E21: 0.1 | K21: =L21&"-"&M21 -> Agressivo-HOTELÁRIAS | L21: Agressivo | M21: HOTELÁRIAS | N21: 0.1
